Workbook

Sheet Menu
B2: Video Tutorial
B3: =HYPERLINK("https://docs.google.com/spreadsheets/d/1e2BOHVwG__zzJXOYlk6mqBmkq1gTDD6SafJrFhAFJMM/edit?gid=346688937#gid=346688937","Check Off Releases and Sustainings") -> Check Off Releases and Sustainings | E3: Status Board
B5: Pulpit Friendly Pages | E5: Assignments
B6: Charlotte | C6: {=COUNTIFs( INDEX(Sustainings!$A:$Z, 0, MATCH(B6, Sustainings!$3:$3, 0)), FALSE,Sustainings!O:O,"Active" )+COUNTIFs('Status Board'!$D:$D,$B6,'Status Board'!$E:$E,"Set Apart")+COUNTIFs('Status Board'!$D:$D,$B6,'Status Board'!$E:$E,"Ordaining")+COUNTIFs('Status Board'!$D:$D,$B6,'Status Board'!$E:$E,"Training")} -> 3 | E6: Rawson | F6: =countifs('Status Board'!F:F,$E6,'Status Board'!E:E,"<>" & "Training")+countifs('Status Board'!G:G,$E6,'Status Board'!E:E,"Training") -> 0
B7: Holt | C7: {=COUNTIFs( INDEX(Sustainings!$A:$Z, 0, MATCH(B7, Sustainings!$3:$3, 0)), FALSE,Sustainings!O:O,"Active" )+COUNTIFs('Status Board'!$D:$D,$B7,'Status Board'!$E:$E,"Set Apart")+COUNTIFs('Status Board'!$D:$D,$B7,'Status Board'!$E:$E,"Ordaining")+COUNTIFs('Status Board'!$D:$D,$B7,'Status Board'!$E:$E,"Training")} -> 1 | E7: Earl | F7: =countifs('Status Board'!F:F,$E7,'Status Board'!E:E,"<>" & "Training")+countifs('Status Board'!G:G,$E7,'Status Board'!E:E,"Training") -> 8
B8: Jackson | C8: {=COUNTIFs( INDEX(Sustainings!$A:$Z, 0, MATCH(B8, Sustainings!$3:$3, 0)), FALSE,Sustainings!O:O,"Active" )+COUNTIFs('Status Board'!$D:$D,$B8,'Status Board'!$E:$E,"Set Apart")+COUNTIFs('Status Board'!$D:$D,$B8,'Status Board'!$E:$E,"Ordaining")+COUNTIFs('Status Board'!$D:$D,$B8,'Status Board'!$E:$E,"Training")} -> 1 | E8: Pierce | F8: =countifs('Status Board'!F:F,$E8,'Status Board'!E:E,"<>" & "Training")+countifs('Status Board'!G:G,$E8,'Status Board'!E:E,"Training") -> 1
B9: Lansing | C9: {=COUNTIFs( INDEX(Sustainings!$A:$Z, 0, MATCH(B9, Sustainings!$3:$3, 0)), FALSE,Sustainings!O:O,"Active" )+COUNTIFs('Status Board'!$D:$D,$B9,'Status Board'!$E:$E,"Set Apart")+COUNTIFs('Status Board'!$D:$D,$B9,'Status Board'!$E:$E,"Ordaining")+COUNTIFs('Status Board'!$D:$D,$B9,'Status Board'!$E:$E,"Training")} -> 4 | E9: Beam | F9: =countifs('Status Board'!F:F,$E9,'Status Board'!E:E,"<>" & "Training")+countifs('Status Board'!G:G,$E9,'Status Board'!E:E,"Training") -> 0
B10: Portland | C10: {=COUNTIFs( INDEX(Sustainings!$A:$Z, 0, MATCH(B10, Sustainings!$3:$3, 0)), FALSE,Sustainings!O:O,"Active" )+COUNTIFs('Status Board'!$D:$D,$B10,'Status Board'!$E:$E,"Set Apart")+COUNTIFs('Status Board'!$D:$D,$B10,'Status Board'!$E:$E,"Ordaining")+COUNTIFs('Status Board'!$D:$D,$B10,'Status Board'!$E:$E,"Training")} -> 3 | E10: Bills | F10: =countifs('Status Board'!F:F,$E10,'Status Board'!E:E,"<>" & "Training")+countifs('Status Board'!G:G,$E10,'Status Board'!E:E,"Training") -> 0
B11: Owosso | C11: {=COUNTIFs( INDEX(Sustainings!$A:$Z, 0, MATCH(B11, Sustainings!$3:$3, 0)), FALSE,Sustainings!O:O,"Active" )+COUNTIFs('Status Board'!$D:$D,$B11,'Status Board'!$E:$E,"Set Apart")+COUNTIFs('Status Board'!$D:$D,$B11,'Status Board'!$E:$E,"Ordaining")+COUNTIFs('Status Board'!$D:$D,$B11,'Status Board'!$E:$E,"Training")} -> 0 | E11: Conn | F11: =countifs('Status Board'!F:F,$E11,'Status Board'!E:E,"<>" & "Training")+countifs('Status Board'!G:G,$E11,'Status Board'!E:E,"Training") -> 1
B12: St Johns | C12: {=COUNTIFs( INDEX(Sustainings!$A:$Z, 0, MATCH(B12, Sustainings!$3:$3, 0)), FALSE,Sustainings!O:O,"Active" )+COUNTIFs('Status Board'!$D:$D,$B12,'Status Board'!$E:$E,"Set Apart")+COUNTIFs('Status Board'!$D:$D,$B12,'Status Board'!$E:$E,"Ordaining")+COUNTIFs('Status Board'!$D:$D,$B12,'Status Board'!$E:$E,"Training")} -> 0 | E12: Doty | F12: =countifs('Status Board'!F:F,$E12,'Status Board'!E:E,"<>" & "Training")+countifs('Status Board'!G:G,$E12,'Status Board'!E:E,"Training") -> 1
B13: Williamston | C13: {=COUNTIFs( INDEX(Sustainings!$A:$Z, 0, MATCH(B13, Sustainings!$3:$3, 0)), FALSE,Sustainings!O:O,"Active" )+COUNTIFs('Status Board'!$D:$D,$B13,'Status Board'!$E:$E,"Set Apart")+COUNTIFs('Status Board'!$D:$D,$B13,'Status Board'!$E:$E,"Ordaining")+COUNTIFs('Status Board'!$D:$D,$B13,'Status Board'!$E:$E,"Training")} -> 1 | E13: Joseph | F13: =countifs('Status Board'!F:F,$E13,'Status Board'!E:E,"<>" & "Training")+countifs('Status Board'!G:G,$E13,'Status Board'!E:E,"Training") -> 0
B14: YSA | C14: {=COUNTIFs( INDEX(Sustainings!$A:$Z, 0, MATCH(B14, Sustainings!$3:$3, 0)), FALSE,Sustainings!O:O,"Active" )+COUNTIFs('Status Board'!$D:$D,$B14,'Status Board'!$E:$E,"Set Apart")+COUNTIFs('Status Board'!$D:$D,$B14,'Status Board'!$E:$E,"Ordaining")+COUNTIFs('Status Board'!$D:$D,$B14,'Status Board'!$E:$E,"Training")} -> 0 | E14: McCrary | F14: =countifs('Status Board'!F:F,$E14,'Status Board'!E:E,"<>" & "Training")+countifs('Status Board'!G:G,$E14,'Status Board'!E:E,"Training") -> 0
E15: Murdock | F15: =countifs('Status Board'!F:F,$E15,'Status Board'!E:E,"<>" & "Training")+countifs('Status Board'!G:G,$E15,'Status Board'!E:E,"Training") -> 0
B16: Mobile Friendly Version | E16: Nelson | F16: =countifs('Status Board'!F:F,$E16,'Status Board'!E:E,"<>" & "Training")+countifs('Status Board'!G:G,$E16,'Status Board'!E:E,"Training") -> 3
E17: Schafer | F17: =countifs('Status Board'!F:F,$E17,'Status Board'!E:E,"<>" & "Training")+countifs('Status Board'!G:G,$E17,'Status Board'!E:E,"Training") -> 0
E18: B. Thorpe | F18: =countifs('Status Board'!F:F,$E18,'Status Board'!E:E,"<>" & "Training")+countifs('Status Board'!G:G,$E18,'Status Board'!E:E,"Training") -> 2
E19: D. Thorpe | F19: =countifs('Status Board'!F:F,$E19,'Status Board'!E:E,"<>" & "Training")+countifs('Status Board'!G:G,$E19,'Status Board'!E:E,"Training") -> 1
E20: Ward | F20: =countifs('Status Board'!F:F,$E20,'Status Board'!E:E,"<>" & "Training")+countifs('Status Board'!G:G,$E20,'Status Board'!E:E,"Training") -> 0
E21: Leifson | F21: =countifs('Status Board'!F:F,$E21,'Status Board'!E:E,"<>" & "Training")+countifs('Status Board'!G:G,$E21,'Status Board'!E:E,"Training") -> 0
E22: Hilgendorf | F22: =countifs('Status Board'!F:F,$E22,'Status Board'!E:E,"<>" & "Training")+countifs('Status Board'!G:G,$E22,'Status Board'!E:E,"Training") -> 1
E23: Status Board

Sheet Sustainings
A1: Unit Sustainings & Releases
A2: Link to Mobile Version
A3: Individual | B3: Unit | C3: Action | D3: Calling / Office | E3: Charlotte | F3: YSA | G3: Holt | H3: Jackson | I3: Lansing | J3: Owosso | K3: Portland | L3: St Johns | M3: Williamston | N3: Percent | O3: Status | P3: Stake Conf Sustain Date
A4: Brit Quarnberg Fathi | B4: Holt | C4: Release & Thank | D4: Stake Relief Society 2nd Counselor | E4: TRUE | F4: TRUE | G4: TRUE | H4: TRUE | I4: TRUE | J4: TRUE | K4: TRUE | L4: TRUE | M4: TRUE | N4: 1 | O4: Complete | P4: 45170
A5: Holly Hickman | B5: Lansing | C5: Sustain | D5: Stake Relief Society 2nd Counselor | E5: TRUE | F5: TRUE | G5: TRUE | H5: TRUE | I5: TRUE | J5: TRUE | K5: TRUE | L5: TRUE | M5: TRUE | N5: 1 | O5: Complete | P5: 45170
A6: Dawn Meadows | B6: Williamston | C6: Sustain | D6: Assistant Just Serve Coordinator | E6: TRUE | F6: TRUE | G6: TRUE | H6: TRUE | I6: TRUE | J6: TRUE | K6: TRUE | L6: TRUE | M6: TRUE | N6: 1 | O6: Complete | P6: 45170
A7: Eric Hunter | B7: Williamston | C7: Release & Thank | D7: Stake High Councilor and Stake Young Men President | E7: TRUE | F7: TRUE | G7: TRUE | H7: TRUE | I7: TRUE | J7: TRUE | K7: TRUE | L7: TRUE | M7: TRUE | N7: 1 | O7: Complete | P7: 45170
A8: Curtis Ferrin | B8: Lansing | C8: Sustain | D8: Stake High Councilor and Stake Young Men President | E8: TRUE | F8: TRUE | G8: TRUE | H8: TRUE | I8: TRUE | J8: TRUE | K8: TRUE | L8: TRUE | M8: TRUE | N8: 1 | O8: Complete | P8: 45170
A9: Brooke Judd | B9: Charlotte | C9: Release & Thank | D9: Stake Communication Director | E9: TRUE | F9: TRUE | G9: TRUE | H9: TRUE | I9: TRUE | J9: TRUE | K9: TRUE | L9: TRUE | M9: TRUE | N9: 1 | O9: Complete | P9: 45170
A10: Stephanie Farero | B10: Holt | C10: Sustain | D10: Stake Communication Director | E10: TRUE | F10: TRUE | G10: TRUE | H10: TRUE | I10: TRUE | J10: TRUE | K10: TRUE | L10: TRUE | M10: TRUE | N10: 1 | O10: Complete | P10: 45170
A11: Don & Nancy Ward | B11: Williamston | C11: Sustain | D11: Stake Clothing Distribution Specialists | E11: TRUE | F11: TRUE | G11: TRUE | H11: TRUE | I11: TRUE | J11: TRUE | K11: TRUE | L11: TRUE | M11: TRUE | N11: 1 | O11: Complete | P11: 45170
A12: Victoria Hall | B12: Williamston | C12: Sustain | D12: Stake YW 2nd Counselor | E12: TRUE | F12: TRUE | G12: TRUE | H12: TRUE | I12: TRUE | J12: TRUE | K12: TRUE | L12: TRUE | M12: TRUE | N12: 1 | O12: Complete | P12: 45170
A13: Brandon Howard | B13: Lansing | C13: Sustain | D13: Stake YM Secretary | E13: TRUE | F13: TRUE | G13: TRUE | H13: TRUE | I13: TRUE | J13: TRUE | K13: TRUE | L13: TRUE | M13: TRUE | N13: 1 | O13: Complete | P13: 45170
A14: Laura Hunter | B14: Williamston | C14: Release & Thank | D14: Stake Primary 2nd Counselor | E14: TRUE | F14: TRUE | G14: TRUE | H14: TRUE | I14: TRUE | J14: TRUE | K14: TRUE | L14: TRUE | M14: TRUE | N14: 1 | O14: Complete | P14: 45170
A15: Cheryl Kelly | B15: Williamston | C15: Sustain | D15: Stake Primary 2nd Counselor | E15: TRUE | F15: TRUE | G15: TRUE | H15: TRUE | I15: TRUE | J15: TRUE | K15: TRUE | L15: TRUE | M15: TRUE | N15: 1 | O15: Complete | P15: 45170
... A31: Nate Jones | B31: St Johns | C31: Sustain | D31: Stake For the Strength of Youth Rep | E31: TRUE | F31: TRUE | G31: TRUE | H31: TRUE | I31: TRUE | J31: TRUE | K31: TRUE | L31: TRUE | M31: TRUE | N31: 1 | O31: Complete | P31: 45352
A32: Allen Scheck | B32: Williamston | C32: Release & Thank | D32: Stake Executive Secretary | E32: TRUE | F32: TRUE | G32: TRUE | H32: TRUE | I32: TRUE | J32: TRUE | K32: TRUE | L32: TRUE | M32: TRUE | N32: =IF(A32="","",COUNTIF(E32:M32,TRUE)/COUNTA(E32:M32)) -> 1 | O32: Complete | P32: 45536
A33: Chris Hilgendorf | B33: Williamston | C33: Sustain | D33: Stake Executive Secretary | E33: TRUE | F33: TRUE | G33: TRUE | H33: TRUE | I33: TRUE | J33: TRUE | K33: TRUE | L33: TRUE | M33: TRUE | N33: =IF(A33="","",COUNTIF(E33:M33,TRUE)/COUNTA(E33:M33)) -> 1 | O33: Complete | P33: 45536
A34: Elliott Renin Earl | B34: St Johns | C34: Sustain | D34: Elder | L34: TRUE | N34: =If(A34="","",COUNTIF(E34:M34,TRUE)/COUNTA(E34:M34)) -> 1 | O34: Complete | P34: 45536
A35: Mark Bell | B35: Holt | C35: Sustain | D35: High Priest | G35: TRUE | N35: =If(A35="","",COUNTIF(E35:M35,TRUE)/COUNTA(E35:M35)) -> 1 | O35: Complete | P35: 45536
A36: Nick Warren | B36: Lansing | C36: Release & Thank | D36: Stake High Councilor | E36: TRUE | F36: TRUE | G36: TRUE | H36: TRUE | I36: TRUE | J36: TRUE | K36: TRUE | L36: TRUE | M36: TRUE | N36: =If(A36="","",COUNTIF(E36:M36,TRUE)/COUNTA(E36:M36)) -> 1 | O36: Complete | P36: 45536
A37: Ken Bills | B37: Williamston | C37: Sustain | D37: Stake High Councilor | E37: TRUE | F37: TRUE | G37: TRUE | H37: TRUE | I37: TRUE | J37: TRUE | K37: TRUE | L37: TRUE | M37: TRUE | N37: =If(A36="","",COUNTIF(E36:M36,TRUE)/COUNTA(E36:M36)) -> 1 | O37: Complete | P37: 45536
A38: Ian McCrary | B38: Lansing | C38: Sustain | D38: Stake High Councilor | E38: TRUE | F38: TRUE | G38: TRUE | H38: TRUE | I38: TRUE | J38: TRUE | K38: TRUE | L38: TRUE | M38: TRUE | N38: =If(A37="","",COUNTIF(E37:M37,TRUE)/COUNTA(E37:M37)) -> 1 | O38: Complete | P38: 45536
A39: Doug Neil | B39: Williamston | C39: Release & Thank | D39: Asst. Stake Clerk - Finance | E39: TRUE | F39: TRUE | G39: TRUE | H39: TRUE | I39: TRUE | J39: TRUE | K39: TRUE | L39: TRUE | M39: TRUE | N39: =If(A39="","",COUNTIF(E39:M39,TRUE)/COUNTA(E39:M39)) -> 1 | O39: Complete | P39: 45536
A40: Don Ward | B40: Williamston | C40: Sustain | D40: Asst. Stake Clerk - Finance | E40: TRUE | F40: TRUE | G40: TRUE | H40: TRUE | I40: TRUE | J40: TRUE | K40: TRUE | L40: TRUE | M40: TRUE | N40: =If(A39="","",COUNTIF(E39:M39,TRUE)/COUNTA(E39:M39)) -> 1 | O40: Complete | P40: 45536
A41: Landon Bartlett | B41: Williamston | C41: Release & Thank | D41: Stake High Councilor - YM 2nd Counselor | E41: TRUE | F41: TRUE | G41: TRUE | H41: TRUE | I41: TRUE | J41: TRUE | K41: TRUE | L41: TRUE | M41: TRUE | N41: =If(A41="","",COUNTIF(E41:M41,TRUE)/COUNTA(E41:M41)) -> 1 | O41: Complete | P41: 45536
A42: Mark Bell | B42: Holt | C42: Sustain | D42: Stake High Councilor - YM 2nd Counselor | E42: TRUE | F42: TRUE | G42: TRUE | H42: TRUE | I42: TRUE | J42: TRUE | K42: TRUE | L42: TRUE | M42: TRUE | N42: =If(A41="","",COUNTIF(E41:M41,TRUE)/COUNTA(E41:M41)) -> 1 | O42: Complete | P42: 45536
A43: Calvin Vos | B43: YSA | C43: Release & Thank | D43: Stake Assistant executive security | E43: TRUE | F43: TRUE | G43: TRUE | H43: TRUE | I43: TRUE | J43: TRUE | K43: TRUE | L43: TRUE | M43: TRUE | N43: =If(A43="","",COUNTIF(E43:M43,TRUE)/COUNTA(E43:M43)) -> 1 | O43: Complete | P43: 45536
A44: David Hall | B44: Williamston | C44: Release & Thank | D44: Stake High Council | E44: TRUE | F44: TRUE | G44: TRUE | H44: TRUE | I44: TRUE | J44: TRUE | K44: TRUE | L44: TRUE | M44: TRUE | N44: =If(A44="","",COUNTIF(E44:M44,TRUE)/COUNTA(E44:M44)) -> 1 | O44: Complete | P44: 45536
A45: Tom and Stephanie Smith | B45: St Johns | C45: Release & Thank | D45: Stake Single Adult Advisers | E45: TRUE | F45: TRUE | G45: TRUE | H45: TRUE | I45: TRUE | J45: TRUE | K45: TRUE | L45: TRUE | M45: TRUE | N45: =If(A45="","",COUNTIF(E45:M45,TRUE)/COUNTA(E45:M45)) -> 1 | O45: Complete | P45: 45536
A46: David Hall | B46: Williamston | C46: Sustain | D46: Stake YM Specialist | E46: TRUE | F46: TRUE | G46: TRUE | H46: TRUE | I46: TRUE | J46: TRUE | K46: TRUE | L46: TRUE | M46: TRUE | N46: =If(A46="","",COUNTIF(E46:M46,TRUE)/COUNTA(E46:M46)) -> 1 | O46: Complete | P46: 45536
A47: Barry Godwin | B47: Williamston | C47: Sustain | D47: Stake Single Adult Representative | E47: TRUE | F47: TRUE | G47: TRUE | H47: TRUE | I47: TRUE | J47: TRUE | K47: TRUE | L47: TRUE | M47: TRUE | N47: =If(A47="","",COUNTIF(E47:M47,TRUE)/COUNTA(E47:M47)) -> 1 | O47: Complete | P47: 45536
A48: Conan Heiselt | B48: Holt | C48: Sustain | D48: Stake Technology Specialist | E48: TRUE | F48: TRUE | G48: TRUE | H48: TRUE | I48: TRUE | J48: TRUE | K48: TRUE | L48: TRUE | M48: TRUE | N48: =If(A48="","",COUNTIF(E48:M48,TRUE)/COUNTA(E48:M48)) -> 1 | O48: Complete | P48: 45536
A49: Noah Wood | B49: Jackson | C49: Sustain | D49: Elder | H49: TRUE | N49: =If(A49="","",COUNTIF(E49:M49,TRUE)/COUNTA(E49:M49)) -> 1 | O49: Complete | P49: 45536
A50: Travis Sybrowsky | B50: Portland | C50: Sustain | D50: Stake Seminary Teacher | E50: TRUE | F50: TRUE | G50: TRUE | H50: TRUE | I50: TRUE | J50: TRUE | K50: TRUE | L50: TRUE | M50: TRUE | N50: =If(A50="","",COUNTIF(E50:M50,TRUE)/COUNTA(E50:M50)) -> 1 | O50: Complete | P50: 45536
A51: Sue Zimmerlee | B51: Holt | C51: Sustain | D51: Stake Temple and Family History Consultant | E51: TRUE | F51: TRUE | G51: TRUE | H51: TRUE | I51: TRUE | J51: TRUE | K51: TRUE | L51: TRUE | M51: TRUE | N51: =If(A51="","",COUNTIF(E51:M51,TRUE)/COUNTA(E51:M51)) -> 1 | O51: Complete | P51: 45717
A52: Brit Fathi | B52: Holt | C52: Sustain | D52: Stake Temple and Family History Consultant | E52: TRUE | F52: TRUE | G52: TRUE | H52: TRUE | I52: TRUE | J52: TRUE | K52: TRUE | L52: TRUE | M52: TRUE | N52: =If(A52="","",COUNTIF(E52:M52,TRUE)/COUNTA(E52:M52)) -> 1 | O52: Complete | P52: 45717
A53: Maggie Gamble | B53: Williamston | C53: Sustain | D53: Stake JustServe Assistant Coordinator | E53: TRUE | F53: TRUE | G53: TRUE | H53: TRUE | I53: TRUE | J53: TRUE | K53: TRUE | L53: TRUE | M53: TRUE | N53: =If(A53="","",COUNTIF(E53:M53,TRUE)/COUNTA(E53:M53)) -> 1 | O53: Complete | P53: 45717
A54: Stephanie Prosser | B54: Holt | C54: Release & Thank | D54: Stake YW Assistant Camp Director | E54: TRUE | F54: TRUE | G54: TRUE | H54: TRUE | I54: TRUE | J54: TRUE | K54: TRUE | L54: TRUE | M54: TRUE | N54: =If(A54="","",COUNTIF(E54:M54,TRUE)/COUNTA(E54:M54)) -> 1 | O54: Complete | P54: 45717
A55: Whitney Kirkham | B55: St Johns | C55: Sustain | D55: Stake Young Women Assistant Camp Director | E55: TRUE | F55: TRUE | G55: TRUE | H55: TRUE | I55: TRUE | J55: TRUE | K55: TRUE | L55: TRUE | M55: TRUE | N55: =If(A55="","",COUNTIF(E55:M55,TRUE)/COUNTA(E55:M55)) -> 1 | O55: Complete | P55: 45717
...

Sheet Status Board
A1: =IFERROR(__xludf.DUMMYFUNCTION("query(importrange(""https://docs.google.com/spreadsheets/d/1iwIN3yeKgD8IBtajkBMA_Eo__Y1LtWBlom7LvQwfxH4/"",""Status Board!A:I""),""Select Col1, Col2, Col3, Col4, Col5, Col7, Col8, Col9 Where Col1 <> '' and Col5 <> 'Sustain' Order By Col5, Col8, Col7"")"),"Type") -> Type | B1: =IFERROR(__xludf.DUMMYFUNCTION("""COMPUTED_VALUE"""),"Member Name") -> Member Name | C1: =IFERROR(__xludf.DUMMYFUNCTION("""COMPUTED_VALUE"""),"Calling") -> Calling | D1: =IFERROR(__xludf.DUMMYFUNCTION("""COMPUTED_VALUE"""),"Unit") -> Unit | E1: =IFERROR(__xludf.DUMMYFUNCTION("""COMPUTED_VALUE"""),"Current Step") -> Current Step | F1: =IFERROR(__xludf.DUMMYFUNCTION("""COMPUTED_VALUE"""),"Assigned to Extend Calling / Release") -> Assigned to Extend Calling / Release | G1: =IFERROR(__xludf.DUMMYFUNCTION("""COMPUTED_VALUE"""),"Assigned Trainer") -> Assigned Trainer | H1: =IFERROR(__xludf.DUMMYFUNCTION("""COMPUTED_VALUE"""),"Hyperlink") -> Hyperlink
A2: =IFERROR(__xludf.DUMMYFUNCTION("""COMPUTED_VALUE"""),"No Releasings") -> No Releasings | B2: =IFERROR(__xludf.DUMMYFUNCTION("""COMPUTED_VALUE""")," ") | C2: =IFERROR(__xludf.DUMMYFUNCTION("""COMPUTED_VALUE""")," ") | D2: =IFERROR(__xludf.DUMMYFUNCTION("""COMPUTED_VALUE""")," ") | E2: =IFERROR(__xludf.DUMMYFUNCTION("""COMPUTED_VALUE""")," ") | F2: =IFERROR(__xludf.DUMMYFUNCTION("""COMPUTED_VALUE""")," ") | G2: =IFERROR(__xludf.DUMMYFUNCTION("""COMPUTED_VALUE""")," ") | H2: =IFERROR(__xludf.DUMMYFUNCTION("""COMPUTED_VALUE""")," ")
A3: =IFERROR(__xludf.DUMMYFUNCTION("""COMPUTED_VALUE"""),"Callings") -> Callings | B3: =IFERROR(__xludf.DUMMYFUNCTION("""COMPUTED_VALUE"""),"Temple McCrary") -> Temple McCrary | C3: =IFERROR(__xludf.DUMMYFUNCTION("""COMPUTED_VALUE"""),"Stake Auditor") -> Stake Auditor | D3: =IFERROR(__xludf.DUMMYFUNCTION("""COMPUTED_VALUE"""),"Lansing") -> Lansing | E3: =IFERROR(__xludf.DUMMYFUNCTION("""COMPUTED_VALUE"""),"Call / Release") -> Call / Release | F3: =IFERROR(__xludf.DUMMYFUNCTION("""COMPUTED_VALUE"""),"Pierce") -> Pierce | H3: =IFERROR(__xludf.DUMMYFUNCTION("""COMPUTED_VALUE"""),"https://docs.google.com/forms/d/e/1FAIpQLSd37AKX0Ca1Yeje6eC6NuliFZj5Spn7I7mXRsa9kBsXMqB-Ag/viewform?edit2=2_ABaOnuc084FrjG7zAzRmpPq49Y4JP88xiAcq-g7-VvQwWFeceQLWBMs_PDHeU79-Vo2bATc") -> https://docs.google.com/forms/d/e/1FAIpQLSd37AKX0Ca1Yeje6eC6NuliFZj5Spn7I7mXRsa9kBsXMqB-Ag/viewform?edit2=2_ABaOnuc084FrjG7zAzRmpPq49Y4JP88xiAcq-g7-VvQwWFeceQLWBMs_PDHeU79-Vo2bATc
A4: =IFERROR(__xludf.DUMMYFUNCTION("""COMPUTED_VALUE"""),"Ordinations") -> Ordinations | B4: =IFERROR(__xludf.DUMMYFUNCTION("""COMPUTED_VALUE"""),"Taylor Smith") -> Taylor Smith | C4: =IFERROR(__xludf.DUMMYFUNCTION("""COMPUTED_VALUE"""),"High Priest") -> High Priest | D4: =IFERROR(__xludf.DUMMYFUNCTION("""COMPUTED_VALUE"""),"Lansing") -> Lansing | E4: =IFERROR(__xludf.DUMMYFUNCTION("""COMPUTED_VALUE"""),"Cancelled") -> Cancelled | G4: =IFERROR(__xludf.DUMMYFUNCTION("""COMPUTED_VALUE""")," ") | H4: =IFERROR(__xludf.DUMMYFUNCTION("""COMPUTED_VALUE"""),"https://docs.google.com/forms/d/e/1FAIpQLScKfK1Xq_AfFRyZkOlyT2n4Ugr8FdePyUxPct4kYLgKJ3YlMQ/viewform?edit2=2_ABaOnufrbZEpQ1VYeN9BXUBQ6v1OzvXmTFVGlu68JTR1rShH00C-sT1ViaSxcZ8c5g36hTc") -> https://docs.google.com/forms/d/e/1FAIpQLScKfK1Xq_AfFRyZkOlyT2n4Ugr8FdePyUxPct4kYLgKJ3YlMQ/viewform?edit2=2_ABaOnufrbZEpQ1VYeN9BXUBQ6v1OzvXmTFVGlu68JTR1rShH00C-sT1ViaSxcZ8c5g36hTc
A5: =IFERROR(__xludf.DUMMYFUNCTION("""COMPUTED_VALUE"""),"Ordinations") -> Ordinations | B5: =IFERROR(__xludf.DUMMYFUNCTION("""COMPUTED_VALUE"""),"Clayton Hoekwater") -> Clayton Hoekwater | C5: =IFERROR(__xludf.DUMMYFUNCTION("""COMPUTED_VALUE"""),"Elder") -> Elder | D5: =IFERROR(__xludf.DUMMYFUNCTION("""COMPUTED_VALUE"""),"YSA") -> YSA | E5: =IFERROR(__xludf.DUMMYFUNCTION("""COMPUTED_VALUE"""),"Certificate") -> Certificate | F5: =IFERROR(__xludf.DUMMYFUNCTION("""COMPUTED_VALUE"""),"Conn") -> Conn | G5: =IFERROR(__xludf.DUMMYFUNCTION("""COMPUTED_VALUE""")," ") | H5: =IFERROR(__xludf.DUMMYFUNCTION("""COMPUTED_VALUE"""),"https://docs.google.com/forms/d/e/1FAIpQLScKfK1Xq_AfFRyZkOlyT2n4Ugr8FdePyUxPct4kYLgKJ3YlMQ/viewform?edit2=2_ABaOnucIF0bUlpImPx8G5Cbwlu76fG6A5FGJO9bhSnfweqQLIYVGJ5NGuH1wd-Vrzig1ARY") -> https://docs.google.com/forms/d/e/1FAIpQLScKfK1Xq_AfFRyZkOlyT2n4Ugr8FdePyUxPct4kYLgKJ3YlMQ/viewform?edit2=2_ABaOnucIF0bUlpImPx8G5Cbwlu76fG6A5FGJO9bhSnfweqQLIYVGJ5NGuH1wd-Vrzig1ARY
A6: =IFERROR(__xludf.DUMMYFUNCTION("""COMPUTED_VALUE"""),"Ordinations") -> Ordinations | B6: =IFERROR(__xludf.DUMMYFUNCTION("""COMPUTED_VALUE"""),"Skyler Roper") -> Skyler Roper | C6: =IFERROR(__xludf.DUMMYFUNCTION("""COMPUTED_VALUE"""),"High Priest") -> High Priest | D6: =IFERROR(__xludf.DUMMYFUNCTION("""COMPUTED_VALUE"""),"Portland") -> Portland | E6: =IFERROR(__xludf.DUMMYFUNCTION("""COMPUTED_VALUE"""),"Certificate") -> Certificate | F6: =IFERROR(__xludf.DUMMYFUNCTION("""COMPUTED_VALUE"""),"Doty") -> Doty | G6: =IFERROR(__xludf.DUMMYFUNCTION("""COMPUTED_VALUE""")," ") | H6: =IFERROR(__xludf.DUMMYFUNCTION("""COMPUTED_VALUE"""),"https://docs.google.com/forms/d/e/1FAIpQLScKfK1Xq_AfFRyZkOlyT2n4Ugr8FdePyUxPct4kYLgKJ3YlMQ/viewform?edit2=2_ABaOnucvgZ8hcmHj8eo8Gttfaa2Xb_k25Mz2N0V6ThqYfwGsiep8vt9_VOKJTNSs6iScXCU") -> https://docs.google.com/forms/d/e/1FAIpQLScKfK1Xq_AfFRyZkOlyT2n4Ugr8FdePyUxPct4kYLgKJ3YlMQ/viewform?edit2=2_ABaOnucvgZ8hcmHj8eo8Gttfaa2Xb_k25Mz2N0V6ThqYfwGsiep8vt9_VOKJTNSs6iScXCU
A7: =IFERROR(__xludf.DUMMYFUNCTION("""COMPUTED_VALUE"""),"Ordinations") -> Ordinations | B7: =IFERROR(__xludf.DUMMYFUNCTION("""COMPUTED_VALUE"""),"Gavin Johnson") -> Gavin Johnson | C7: =IFERROR(__xludf.DUMMYFUNCTION("""COMPUTED_VALUE"""),"High Priest") -> High Priest | D7: =IFERROR(__xludf.DUMMYFUNCTION("""COMPUTED_VALUE"""),"Lansing") -> Lansing | E7: =IFERROR(__xludf.DUMMYFUNCTION("""COMPUTED_VALUE"""),"Ordination") -> Ordination | F7: =IFERROR(__xludf.DUMMYFUNCTION("""COMPUTED_VALUE"""),"Earl") -> Earl | G7: =IFERROR(__xludf.DUMMYFUNCTION("""COMPUTED_VALUE""")," ") | H7: =IFERROR(__xludf.DUMMYFUNCTION("""COMPUTED_VALUE"""),"https://docs.google.com/forms/d/e/1FAIpQLScKfK1Xq_AfFRyZkOlyT2n4Ugr8FdePyUxPct4kYLgKJ3YlMQ/viewform?edit2=2_ABaOnucYlNz1YoXLPBAYyST6WlmELb1kBnM9BfkUaTxKov-rM8gB0ieRnkyVKFnayrBrwdE") -> https://docs.google.com/forms/d/e/1FAIpQLScKfK1Xq_AfFRyZkOlyT2n4Ugr8FdePyUxPct4kYLgKJ3YlMQ/viewform?edit2=2_ABaOnucYlNz1YoXLPBAYyST6WlmELb1kBnM9BfkUaTxKov-rM8gB0ieRnkyVKFnayrBrwdE
A8: =IFERROR(__xludf.DUMMYFUNCTION("""COMPUTED_VALUE"""),"Ordinations") -> Ordinations | B8: =IFERROR(__xludf.DUMMYFUNCTION("""COMPUTED_VALUE"""),"Tristan Packard") -> Tristan Packard | C8: =IFERROR(__xludf.DUMMYFUNCTION("""COMPUTED_VALUE"""),"High Priest") -> High Priest | D8: =IFERROR(__xludf.DUMMYFUNCTION("""COMPUTED_VALUE"""),"Lansing") -> Lansing | E8: =IFERROR(__xludf.DUMMYFUNCTION("""COMPUTED_VALUE"""),"Ordination") -> Ordination | F8: =IFERROR(__xludf.DUMMYFUNCTION("""COMPUTED_VALUE"""),"Earl") -> Earl | G8: =IFERROR(__xludf.DUMMYFUNCTION("""COMPUTED_VALUE""")," ") | H8: =IFERROR(__xludf.DUMMYFUNCTION("""COMPUTED_VALUE"""),"https://docs.google.com/forms/d/e/1FAIpQLScKfK1Xq_AfFRyZkOlyT2n4Ugr8FdePyUxPct4kYLgKJ3YlMQ/viewform?edit2=2_ABaOnucINqfbL2HNtyT2-rdXO1PHIOPKQtPP-hALfOhqsXkOd_XPh6FLRTCqadIMuXnaou0") -> https://docs.google.com/forms/d/e/1FAIpQLScKfK1Xq_AfFRyZkOlyT2n4Ugr8FdePyUxPct4kYLgKJ3YlMQ/viewform?edit2=2_ABaOnucINqfbL2HNtyT2-rdXO1PHIOPKQtPP-hALfOhqsXkOd_XPh6FLRTCqadIMuXnaou0
A9: =IFERROR(__xludf.DUMMYFUNCTION("""COMPUTED_VALUE"""),"Callings") -> Callings | B9: =IFERROR(__xludf.DUMMYFUNCTION("""COMPUTED_VALUE"""),"Tristan Packard") -> Tristan Packard | C9: =IFERROR(__xludf.DUMMYFUNCTION("""COMPUTED_VALUE"""),"Bishopric 2nd Counselor") -> Bishopric 2nd Counselor | D9: =IFERROR(__xludf.DUMMYFUNCTION("""COMPUTED_VALUE"""),"Lansing") -> Lansing | E9: =IFERROR(__xludf.DUMMYFUNCTION("""COMPUTED_VALUE"""),"Set Apart") -> Set Apart | F9: =IFERROR(__xludf.DUMMYFUNCTION("""COMPUTED_VALUE"""),"Earl") -> Earl | G9: =IFERROR(__xludf.DUMMYFUNCTION("""COMPUTED_VALUE"""),"Earl") -> Earl | H9: =IFERROR(__xludf.DUMMYFUNCTION("""COMPUTED_VALUE"""),"https://docs.google.com/forms/d/e/1FAIpQLSd37AKX0Ca1Yeje6eC6NuliFZj5Spn7I7mXRsa9kBsXMqB-Ag/viewform?edit2=2_ABaOnucU6DOq6qcvz42zkHjhZlqUckdI_P7WQvTHT6kRvXPS0nedw-Lqwshw-TPP60rFl40") -> https://docs.google.com/forms/d/e/1FAIpQLSd37AKX0Ca1Yeje6eC6NuliFZj5Spn7I7mXRsa9kBsXMqB-Ag/viewform?edit2=2_ABaOnucU6DOq6qcvz42zkHjhZlqUckdI_P7WQvTHT6kRvXPS0nedw-Lqwshw-TPP60rFl40
A10: =IFERROR(__xludf.DUMMYFUNCTION("""COMPUTED_VALUE"""),"Callings") -> Callings | B10: =IFERROR(__xludf.DUMMYFUNCTION("""COMPUTED_VALUE"""),"Gavin Johnson") -> Gavin Johnson | C10: =IFERROR(__xludf.DUMMYFUNCTION("""COMPUTED_VALUE"""),"Bishopric 1st Counselor") -> Bishopric 1st Counselor | D10: =IFERROR(__xludf.DUMMYFUNCTION("""COMPUTED_VALUE"""),"Lansing") -> Lansing | E10: =IFERROR(__xludf.DUMMYFUNCTION("""COMPUTED_VALUE"""),"Set Apart") -> Set Apart | F10: =IFERROR(__xludf.DUMMYFUNCTION("""COMPUTED_VALUE"""),"Earl") -> Earl | G10: =IFERROR(__xludf.DUMMYFUNCTION("""COMPUTED_VALUE"""),"Earl") -> Earl | H10: =IFERROR(__xludf.DUMMYFUNCTION("""COMPUTED_VALUE"""),"https://docs.google.com/forms/d/e/1FAIpQLSd37AKX0Ca1Yeje6eC6NuliFZj5Spn7I7mXRsa9kBsXMqB-Ag/viewform?edit2=2_ABaOnuerF-9S-0PUnAo-xLIpSHuJa6TuFg8a5-HK4pKoELYuVYouRoOvSYDtqHqjDqv1WPE") -> https://docs.google.com/forms/d/e/1FAIpQLSd37AKX0Ca1Yeje6eC6NuliFZj5Spn7I7mXRsa9kBsXMqB-Ag/viewform?edit2=2_ABaOnuerF-9S-0PUnAo-xLIpSHuJa6TuFg8a5-HK4pKoELYuVYouRoOvSYDtqHqjDqv1WPE
A11: =IFERROR(__xludf.DUMMYFUNCTION("""COMPUTED_VALUE"""),"Callings") -> Callings | B11: =IFERROR(__xludf.DUMMYFUNCTION("""COMPUTED_VALUE"""),"Barbara Miller") -> Barbara Miller | C11: =IFERROR(__xludf.DUMMYFUNCTION("""COMPUTED_VALUE"""),"Stake YW Secretary") -> Stake YW Secretary | D11: =IFERROR(__xludf.DUMMYFUNCTION("""COMPUTED_VALUE"""),"Williamston") -> Williamston | E11: =IFERROR(__xludf.DUMMYFUNCTION("""COMPUTED_VALUE"""),"Training") -> Training | F11: =IFERROR(__xludf.DUMMYFUNCTION("""COMPUTED_VALUE"""),"B. Thorpe") -> B. Thorpe | G11: =IFERROR(__xludf.DUMMYFUNCTION("""COMPUTED_VALUE"""),"B. Thorpe") -> B. Thorpe | H11: =IFERROR(__xludf.DUMMYFUNCTION("""COMPUTED_VALUE"""),"https://docs.google.com/forms/d/e/1FAIpQLSd37AKX0Ca1Yeje6eC6NuliFZj5Spn7I7mXRsa9kBsXMqB-Ag/viewform?edit2=2_ABaOnueqOA9jOURj75fgFVzTPRoS4CvrWRrmHCOIfJ0-em66xU40R2VatgNoW4WQt5tTjMU") -> https://docs.google.com/forms/d/e/1FAIpQLSd37AKX0Ca1Yeje6eC6NuliFZj5Spn7I7mXRsa9kBsXMqB-Ag/viewform?edit2=2_ABaOnueqOA9jOURj75fgFVzTPRoS4CvrWRrmHCOIfJ0-em66xU40R2VatgNoW4WQt5tTjMU
A12: =IFERROR(__xludf.DUMMYFUNCTION("""COMPUTED_VALUE"""),"Callings") -> Callings | B12: =IFERROR(__xludf.DUMMYFUNCTION("""COMPUTED_VALUE"""),"Andrea Lowder") -> Andrea Lowder | C12: =IFERROR(__xludf.DUMMYFUNCTION("""COMPUTED_VALUE"""),"Stake YW 1st Counselor") -> Stake YW 1st Counselor | D12: =IFERROR(__xludf.DUMMYFUNCTION("""COMPUTED_VALUE"""),"Holt") -> Holt | E12: =IFERROR(__xludf.DUMMYFUNCTION("""COMPUTED_VALUE"""),"Training") -> Training | F12: =IFERROR(__xludf.DUMMYFUNCTION("""COMPUTED_VALUE"""),"B. Thorpe") -> B. Thorpe | G12: =IFERROR(__xludf.DUMMYFUNCTION("""COMPUTED_VALUE"""),"B. Thorpe") -> B. Thorpe | H12: =IFERROR(__xludf.DUMMYFUNCTION("""COMPUTED_VALUE"""),"https://docs.google.com/forms/d/e/1FAIpQLSd37AKX0Ca1Yeje6eC6NuliFZj5Spn7I7mXRsa9kBsXMqB-Ag/viewform?edit2=2_ABaOnudeQNpZK8qo5P01o5m8u1nK-nidTP440bH0iWjs2673t7t6cup8pQiFCCzYZAU0aPQ") -> https://docs.google.com/forms/d/e/1FAIpQLSd37AKX0Ca1Yeje6eC6NuliFZj5Spn7I7mXRsa9kBsXMqB-Ag/viewform?edit2=2_ABaOnudeQNpZK8qo5P01o5m8u1nK-nidTP440bH0iWjs2673t7t6cup8pQiFCCzYZAU0aPQ
A13: =IFERROR(__xludf.DUMMYFUNCTION("""COMPUTED_VALUE"""),"Callings") -> Callings | B13: =IFERROR(__xludf.DUMMYFUNCTION("""COMPUTED_VALUE"""),"Jonathan Boegler") -> Jonathan Boegler | C13: =IFERROR(__xludf.DUMMYFUNCTION("""COMPUTED_VALUE"""),"EQ 1st Counselor") -> EQ 1st Counselor | D13: =IFERROR(__xludf.DUMMYFUNCTION("""COMPUTED_VALUE"""),"Jackson") -> Jackson | E13: =IFERROR(__xludf.DUMMYFUNCTION("""COMPUTED_VALUE"""),"Training") -> Training | F13: =IFERROR(__xludf.DUMMYFUNCTION("""COMPUTED_VALUE"""),"D. Thorpe") -> D. Thorpe | G13: =IFERROR(__xludf.DUMMYFUNCTION("""COMPUTED_VALUE"""),"D. Thorpe") -> D. Thorpe | H13: =IFERROR(__xludf.DUMMYFUNCTION("""COMPUTED_VALUE"""),"https://docs.google.com/forms/d/e/1FAIpQLSd37AKX0Ca1Yeje6eC6NuliFZj5Spn7I7mXRsa9kBsXMqB-Ag/viewform?edit2=2_ABaOnuff1NqAKnZeZFWYAZ37X-J5lZZRuI-4HxjIyakngMffc9MgN7mqhOsy4yZwbSwlM5A") -> https://docs.google.com/forms/d/e/1FAIpQLSd37AKX0Ca1Yeje6eC6NuliFZj5Spn7I7mXRsa9kBsXMqB-Ag/viewform?edit2=2_ABaOnuff1NqAKnZeZFWYAZ37X-J5lZZRuI-4HxjIyakngMffc9MgN7mqhOsy4yZwbSwlM5A
A14: =IFERROR(__xludf.DUMMYFUNCTION("""COMPUTED_VALUE"""),"Callings") -> Callings | B14: =IFERROR(__xludf.DUMMYFUNCTION("""COMPUTED_VALUE"""),"Mark Witbeck") -> Mark Witbeck | C14: =IFERROR(__xludf.DUMMYFUNCTION("""COMPUTED_VALUE"""),"Branch Presidency 2nd Counselor") -> Branch Presidency 2nd Counselor | D14: =IFERROR(__xludf.DUMMYFUNCTION("""COMPUTED_VALUE"""),"Portland") -> Portland | E14: =IFERROR(__xludf.DUMMYFUNCTION("""COMPUTED_VALUE"""),"Training") -> Training | F14: =IFERROR(__xludf.DUMMYFUNCTION("""COMPUTED_VALUE"""),"Earl") -> Earl | G14: =IFERROR(__xludf.DUMMYFUNCTION("""COMPUTED_VALUE"""),"Earl") -> Earl | H14: =IFERROR(__xludf.DUMMYFUNCTION("""COMPUTED_VALUE"""),"https://docs.google.com/forms/d/e/1FAIpQLSd37AKX0Ca1Yeje6eC6NuliFZj5Spn7I7mXRsa9kBsXMqB-Ag/viewform?edit2=2_ABaOnuf6drCWA-IZBlNqDAotDEssKORUs-S1i6ryHOYbNmm5r74FiPSdK2RgyzyGz8V24y8") -> https://docs.google.com/forms/d/e/1FAIpQLSd37AKX0Ca1Yeje6eC6NuliFZj5Spn7I7mXRsa9kBsXMqB-Ag/viewform?edit2=2_ABaOnuf6drCWA-IZBlNqDAotDEssKORUs-S1i6ryHOYbNmm5r74FiPSdK2RgyzyGz8V24y8
A15: =IFERROR(__xludf.DUMMYFUNCTION("""COMPUTED_VALUE"""),"Callings") -> Callings | B15: =IFERROR(__xludf.DUMMYFUNCTION("""COMPUTED_VALUE"""),"Del Sterling") -> Del Sterling | C15: =IFERROR(__xludf.DUMMYFUNCTION("""COMPUTED_VALUE"""),"Branch Presidency 1st Counselor") -> Branch Presidency 1st Counselor | D15: =IFERROR(__xludf.DUMMYFUNCTION("""COMPUTED_VALUE"""),"Portland") -> Portland | E15: =IFERROR(__xludf.DUMMYFUNCTION("""COMPUTED_VALUE"""),"Training") -> Training | F15: =IFERROR(__xludf.DUMMYFUNCTION("""COMPUTED_VALUE"""),"Earl") -> Earl | G15: =IFERROR(__xludf.DUMMYFUNCTION("""COMPUTED_VALUE"""),"Earl") -> Earl | H15: =IFERROR(__xludf.DUMMYFUNCTION("""COMPUTED_VALUE"""),"https://docs.google.com/forms/d/e/1FAIpQLSd37AKX0Ca1Yeje6eC6NuliFZj5Spn7I7mXRsa9kBsXMqB-Ag/viewform?edit2=2_ABaOnucXYh7TXzTa8Eiqh6G2iI9SDkB9z7HxXc-muPtZY1lxw5j5SfdnONWyGViUYdQGjOE") -> https://docs.google.com/forms/d/e/1FAIpQLSd37AKX0Ca1Yeje6eC6NuliFZj5Spn7I7mXRsa9kBsXMqB-Ag/viewform?edit2=2_ABaOnucXYh7TXzTa8Eiqh6G2iI9SDkB9z7HxXc-muPtZY1lxw5j5SfdnONWyGViUYdQGjOE
A16: =IFERROR(__xludf.DUMMYFUNCTION("""COMPUTED_VALUE"""),"Callings") -> Callings | B16: =IFERROR(__xludf.DUMMYFUNCTION("""COMPUTED_VALUE"""),"Tanner Hickman") -> Tanner Hickman | C16: =IFERROR(__xludf.DUMMYFUNCTION("""COMPUTED_VALUE"""),"Bishop") -> Bishop | D16: =IFERROR(__xludf.DUMMYFUNCTION("""COMPUTED_VALUE"""),"Lansing") -> Lansing | E16: =IFERROR(__xludf.DUMMYFUNCTION("""COMPUTED_VALUE"""),"Training") -> Training | F16: =IFERROR(__xludf.DUMMYFUNCTION("""COMPUTED_VALUE"""),"Rawson") -> Rawson | G16: =IFERROR(__xludf.DUMMYFUNCTION("""COMPUTED_VALUE"""),"Earl") -> Earl | H16: =IFERROR(__xludf.DUMMYFUNCTION("""COMPUTED_VALUE"""),"https://docs.google.com/forms/d/e/1FAIpQLSd37AKX0Ca1Yeje6eC6NuliFZj5Spn7I7mXRsa9kBsXMqB-Ag/viewform?edit2=2_ABaOnuf2j7989Basd7RqeWk5ShbfC9vglbQAYME_8G0y9KgxN5a2Sxu33yjZSF-7UYqZu8U") -> https://docs.google.com/forms/d/e/1FAIpQLSd37AKX0Ca1Yeje6eC6NuliFZj5Spn7I7mXRsa9kBsXMqB-Ag/viewform?edit2=2_ABaOnuf2j7989Basd7RqeWk5ShbfC9vglbQAYME_8G0y9KgxN5a2Sxu33yjZSF-7UYqZu8U
A17: =IFERROR(__xludf.DUMMYFUNCTION("""COMPUTED_VALUE"""),"Callings") -> Callings | B17: =IFERROR(__xludf.DUMMYFUNCTION("""COMPUTED_VALUE"""),"Skyler Roper") -> Skyler Roper | C17: =IFERROR(__xludf.DUMMYFUNCTION("""COMPUTED_VALUE"""),"Branch President") -> Branch President | D17: =IFERROR(__xludf.DUMMYFUNCTION("""COMPUTED_VALUE"""),"Portland") -> Portland | E17: =IFERROR(__xludf.DUMMYFUNCTION("""COMPUTED_VALUE"""),"Training") -> Training | F17: =IFERROR(__xludf.DUMMYFUNCTION("""COMPUTED_VALUE"""),"Rawson") -> Rawson | G17: =IFERROR(__xludf.DUMMYFUNCTION("""COMPUTED_VALUE"""),"Earl") -> Earl | H17: =IFERROR(__xludf.DUMMYFUNCTION("""COMPUTED_VALUE"""),"https://docs.google.com/forms/d/e/1FAIpQLSd37AKX0Ca1Yeje6eC6NuliFZj5Spn7I7mXRsa9kBsXMqB-Ag/viewform?edit2=2_ABaOnueza0QWbrwz8T7sWbuoj8RQ0uTYVPMjIOquJLrwomLqVasBXKQ7q4oPdU42q5sebnY") -> https://docs.google.com/forms/d/e/1FAIpQLSd37AKX0Ca1Yeje6eC6NuliFZj5Spn7I7mXRsa9kBsXMqB-Ag/viewform?edit2=2_ABaOnueza0QWbrwz8T7sWbuoj8RQ0uTYVPMjIOquJLrwomLqVasBXKQ7q4oPdU42q5sebnY
A18: =IFERROR(__xludf.DUMMYFUNCTION("""COMPUTED_VALUE"""),"Callings") -> Callings | B18: =IFERROR(__xludf.DUMMYFUNCTION("""COMPUTED_VALUE"""),"Sawyer Barney") -> Sawyer Barney | C18: =IFERROR(__xludf.DUMMYFUNCTION("""COMPUTED_VALUE"""),"Executive Secretary") -> Executive Secretary | D18: =IFERROR(__xludf.DUMMYFUNCTION("""COMPUTED_VALUE"""),"Lansing") -> Lansing | E18: =IFERROR(__xludf.DUMMYFUNCTION("""COMPUTED_VALUE"""),"Training") -> Training | F18: =IFERROR(__xludf.DUMMYFUNCTION("""COMPUTED_VALUE"""),"Earl") -> Earl | G18: =IFERROR(__xludf.DUMMYFUNCTION("""COMPUTED_VALUE"""),"Hilgendorf") -> Hilgendorf | H18: =IFERROR(__xludf.DUMMYFUNCTION("""COMPUTED_VALUE"""),"https://docs.google.com/forms/d/e/1FAIpQLSd37AKX0Ca1Yeje6eC6NuliFZj5Spn7I7mXRsa9kBsXMqB-Ag/viewform?edit2=2_ABaOnue8mI5AYqilJnQ-23IHeU09ipqfAONkBPAhQ3a3okU2s71v_L1uHn7A2GfefVIT5vE") -> https://docs.google.com/forms/d/e/1FAIpQLSd37AKX0Ca1Yeje6eC6NuliFZj5Spn7I7mXRsa9kBsXMqB-Ag/viewform?edit2=2_ABaOnue8mI5AYqilJnQ-23IHeU09ipqfAONkBPAhQ3a3okU2s71v_L1uHn7A2GfefVIT5vE
A19: =IFERROR(__xludf.DUMMYFUNCTION("""COMPUTED_VALUE"""),"Callings") -> Callings | B19: =IFERROR(__xludf.DUMMYFUNCTION("""COMPUTED_VALUE"""),"Giacinto Lucci Sr.") -> Giacinto Lucci Sr. | C19: =IFERROR(__xludf.DUMMYFUNCTION("""COMPUTED_VALUE"""),"EQ 1st Counselor") -> EQ 1st Counselor | D19: =IFERROR(__xludf.DUMMYFUNCTION("""COMPUTED_VALUE"""),"Charlotte") -> Charlotte | E19: =IFERROR(__xludf.DUMMYFUNCTION("""COMPUTED_VALUE"""),"Training") -> Training | F19: =IFERROR(__xludf.DUMMYFUNCTION("""COMPUTED_VALUE"""),"Nelson") -> Nelson | G19: =IFERROR(__xludf.DUMMYFUNCTION("""COMPUTED_VALUE"""),"Nelson") -> Nelson | H19: =IFERROR(__xludf.DUMMYFUNCTION("""COMPUTED_VALUE"""),"https://docs.google.com/forms/d/e/1FAIpQLSd37AKX0Ca1Yeje6eC6NuliFZj5Spn7I7mXRsa9kBsXMqB-Ag/viewform?edit2=2_ABaOnufG4qkFQOtlvqNs92E6J7QIRFpabq77LhYs1EKoIUylzebWNv8mFo_PoidwofkyZ0Y") -> https://docs.google.com/forms/d/e/1FAIpQLSd37AKX0Ca1Yeje6eC6NuliFZj5Spn7I7mXRsa9kBsXMqB-Ag/viewform?edit2=2_ABaOnufG4qkFQOtlvqNs92E6J7QIRFpabq77LhYs1EKoIUylzebWNv8mFo_PoidwofkyZ0Y
A20: =IFERROR(__xludf.DUMMYFUNCTION("""COMPUTED_VALUE"""),"Callings") -> Callings | B20: =IFERROR(__xludf.DUMMYFUNCTION("""COMPUTED_VALUE"""),"David Polhamus") -> David Polhamus | C20: =IFERROR(__xludf.DUMMYFUNCTION("""COMPUTED_VALUE"""),"EQ 2nd Counselor") -> EQ 2nd Counselor | D20: =IFERROR(__xludf.DUMMYFUNCTION("""COMPUTED_VALUE"""),"Charlotte") -> Charlotte | E20: =IFERROR(__xludf.DUMMYFUNCTION("""COMPUTED_VALUE"""),"Training") -> Training | F20: =IFERROR(__xludf.DUMMYFUNCTION("""COMPUTED_VALUE"""),"Nelson") -> Nelson | G20: =IFERROR(__xludf.DUMMYFUNCTION("""COMPUTED_VALUE"""),"Nelson") -> Nelson | H20: =IFERROR(__xludf.DUMMYFUNCTION("""COMPUTED_VALUE"""),"https://docs.google.com/forms/d/e/1FAIpQLSd37AKX0Ca1Yeje6eC6NuliFZj5Spn7I7mXRsa9kBsXMqB-Ag/viewform?edit2=2_ABaOnueYWLUCkhOyJAhdd6sl35WX-SzQl1fVfL0acBK39C3PrSGDfh5FKCpV-EWK10pwrqQ") -> https://docs.google.com/forms/d/e/1FAIpQLSd37AKX0Ca1Yeje6eC6NuliFZj5Spn7I7mXRsa9kBsXMqB-Ag/viewform?edit2=2_ABaOnueYWLUCkhOyJAhdd6sl35WX-SzQl1fVfL0acBK39C3PrSGDfh5FKCpV-EWK10pwrqQ
A21: =IFERROR(__xludf.DUMMYFUNCTION("""COMPUTED_VALUE"""),"Callings") -> Callings | B21: =IFERROR(__xludf.DUMMYFUNCTION("""COMPUTED_VALUE"""),"Jordan Coker") -> Jordan Coker | C21: =IFERROR(__xludf.DUMMYFUNCTION("""COMPUTED_VALUE"""),"Elders Quorum President") -> Elders Quorum President | D21: =IFERROR(__xludf.DUMMYFUNCTION("""COMPUTED_VALUE"""),"Charlotte") -> Charlotte | E21: =IFERROR(__xludf.DUMMYFUNCTION("""COMPUTED_VALUE"""),"Training") -> Training | F21: =IFERROR(__xludf.DUMMYFUNCTION("""COMPUTED_VALUE"""),"Rawson") -> Rawson | G21: =IFERROR(__xludf.DUMMYFUNCTION("""COMPUTED_VALUE"""),"Nelson") -> Nelson | H21: =IFERROR(__xludf.DUMMYFUNCTION("""COMPUTED_VALUE"""),"https://docs.google.com/forms/d/e/1FAIpQLSd37AKX0Ca1Yeje6eC6NuliFZj5Spn7I7mXRsa9kBsXMqB-Ag/viewform?edit2=2_ABaOnucjwEQQpKVtkpHfLLSdr7wlsJ123jmny_Y0VAZ3t1dzFLz17xf1AylOpEj0gIyz5Dg") -> https://docs.google.com/forms/d/e/1FAIpQLSd37AKX0Ca1Yeje6eC6NuliFZj5Spn7I7mXRsa9kBsXMqB-Ag/viewform?edit2=2_ABaOnucjwEQQpKVtkpHfLLSdr7wlsJ123jmny_Y0VAZ3t1dzFLz17xf1AylOpEj0gIyz5Dg

Sheet Stake Conference
A1: =IFERROR(__xludf.DUMMYFUNCTION("query(Sustainings!A3:P1000,""Select A,B,C,D,O Where O = 'Stake Conf'"")"),"Individual") -> Individual | B1: =IFERROR(__xludf.DUMMYFUNCTION("""COMPUTED_VALUE"""),"Unit") -> Unit | C1: =IFERROR(__xludf.DUMMYFUNCTION("""COMPUTED_VALUE"""),"Action") -> Action | D1: =IFERROR(__xludf.DUMMYFUNCTION("""COMPUTED_VALUE"""),"Calling / Office") -> Calling / Office | E1: =IFERROR(__xludf.DUMMYFUNCTION("""COMPUTED_VALUE"""),"Status") -> Status
A2: =IFERROR(__xludf.DUMMYFUNCTION("""COMPUTED_VALUE"""),"Clayton Hoekwater") -> Clayton Hoekwater | B2: =IFERROR(__xludf.DUMMYFUNCTION("""COMPUTED_VALUE"""),"YSA") -> YSA | C2: =IFERROR(__xludf.DUMMYFUNCTION("""COMPUTED_VALUE"""),"Sustain") -> Sustain | D2: =IFERROR(__xludf.DUMMYFUNCTION("""COMPUTED_VALUE"""),"Elder") -> Elder | E2: =IFERROR(__xludf.DUMMYFUNCTION("""COMPUTED_VALUE"""),"Stake Conf") -> Stake Conf
A3: =IFERROR(__xludf.DUMMYFUNCTION("""COMPUTED_VALUE"""),"Skyler Roper") -> Skyler Roper | B3: =IFERROR(__xludf.DUMMYFUNCTION("""COMPUTED_VALUE"""),"Portland") -> Portland | C3: =IFERROR(__xludf.DUMMYFUNCTION("""COMPUTED_VALUE"""),"Sustain") -> Sustain | D3: =IFERROR(__xludf.DUMMYFUNCTION("""COMPUTED_VALUE"""),"High Priest") -> High Priest | E3: =IFERROR(__xludf.DUMMYFUNCTION("""COMPUTED_VALUE"""),"Stake Conf") -> Stake Conf
A4: =IFERROR(__xludf.DUMMYFUNCTION("""COMPUTED_VALUE"""),"Tristan Packard") -> Tristan Packard | B4: =IFERROR(__xludf.DUMMYFUNCTION("""COMPUTED_VALUE"""),"Lansing") -> Lansing | C4: =IFERROR(__xludf.DUMMYFUNCTION("""COMPUTED_VALUE"""),"Sustain") -> Sustain | D4: =IFERROR(__xludf.DUMMYFUNCTION("""COMPUTED_VALUE"""),"High Priest") -> High Priest | E4: =IFERROR(__xludf.DUMMYFUNCTION("""COMPUTED_VALUE"""),"Stake Conf") -> Stake Conf
A5: =IFERROR(__xludf.DUMMYFUNCTION("""COMPUTED_VALUE"""),"Gavin Johnson") -> Gavin Johnson | B5: =IFERROR(__xludf.DUMMYFUNCTION("""COMPUTED_VALUE"""),"Lansing") -> Lansing | C5: =IFERROR(__xludf.DUMMYFUNCTION("""COMPUTED_VALUE"""),"Sustain") -> Sustain | D5: =IFERROR(__xludf.DUMMYFUNCTION("""COMPUTED_VALUE"""),"High Priest") -> High Priest | E5: =IFERROR(__xludf.DUMMYFUNCTION("""COMPUTED_VALUE"""),"Stake Conf") -> Stake Conf

Sheet History
A1: =IFERROR(__xludf.DUMMYFUNCTION("query(Sustainings!A3:P1000,""Select A,B,C,D,O,P Where P Is Not Null ORDER BY P Desc"")"),"Individual") -> Individual | B1: =IFERROR(__xludf.DUMMYFUNCTION("""COMPUTED_VALUE"""),"Unit") -> Unit | C1: =IFERROR(__xludf.DUMMYFUNCTION("""COMPUTED_VALUE"""),"Action") -> Action | D1: =IFERROR(__xludf.DUMMYFUNCTION("""COMPUTED_VALUE"""),"Calling / Office") -> Calling / Office | E1: =IFERROR(__xludf.DUMMYFUNCTION("""COMPUTED_VALUE"""),"Status") -> Status | F1: =IFERROR(__xludf.DUMMYFUNCTION("""COMPUTED_VALUE"""),"Stake Conf Sustain Date") -> Stake Conf Sustain Date
A2: =IFERROR(__xludf.DUMMYFUNCTION("""COMPUTED_VALUE"""),"David Cramer") -> David Cramer | B2: =IFERROR(__xludf.DUMMYFUNCTION("""COMPUTED_VALUE"""),"Williamston") -> Williamston | C2: =IFERROR(__xludf.DUMMYFUNCTION("""COMPUTED_VALUE"""),"Sustain") -> Sustain | D2: =IFERROR(__xludf.DUMMYFUNCTION("""COMPUTED_VALUE"""),"Elder") -> Elder | E2: =IFERROR(__xludf.DUMMYFUNCTION("""COMPUTED_VALUE"""),"Complete") -> Complete | F2: =IFERROR(__xludf.DUMMYFUNCTION("""COMPUTED_VALUE"""),46089.0) -> 46089
A3: =IFERROR(__xludf.DUMMYFUNCTION("""COMPUTED_VALUE"""),"Ian Webster") -> Ian Webster | B3: =IFERROR(__xludf.DUMMYFUNCTION("""COMPUTED_VALUE"""),"YSA") -> YSA | C3: =IFERROR(__xludf.DUMMYFUNCTION("""COMPUTED_VALUE"""),"Sustain") -> Sustain | D3: =IFERROR(__xludf.DUMMYFUNCTION("""COMPUTED_VALUE"""),"Elder") -> Elder | E3: =IFERROR(__xludf.DUMMYFUNCTION("""COMPUTED_VALUE"""),"Complete") -> Complete | F3: =IFERROR(__xludf.DUMMYFUNCTION("""COMPUTED_VALUE"""),46089.0) -> 46089
A4: =IFERROR(__xludf.DUMMYFUNCTION("""COMPUTED_VALUE"""),"David Polhamus") -> David Polhamus | B4: =IFERROR(__xludf.DUMMYFUNCTION("""COMPUTED_VALUE"""),"Charlotte") -> Charlotte | C4: =IFERROR(__xludf.DUMMYFUNCTION("""COMPUTED_VALUE"""),"Sustain") -> Sustain | D4: =IFERROR(__xludf.DUMMYFUNCTION("""COMPUTED_VALUE"""),"Elder") -> Elder | E4: =IFERROR(__xludf.DUMMYFUNCTION("""COMPUTED_VALUE"""),"Complete") -> Complete | F4: =IFERROR(__xludf.DUMMYFUNCTION("""COMPUTED_VALUE"""),46089.0) -> 46089
A5: =IFERROR(__xludf.DUMMYFUNCTION("""COMPUTED_VALUE"""),"Sean Potter") -> Sean Potter | B5: =IFERROR(__xludf.DUMMYFUNCTION("""COMPUTED_VALUE"""),"Holt") -> Holt | C5: =IFERROR(__xludf.DUMMYFUNCTION("""COMPUTED_VALUE"""),"Sustain") -> Sustain | D5: =IFERROR(__xludf.DUMMYFUNCTION("""COMPUTED_VALUE"""),"Elder") -> Elder | E5: =IFERROR(__xludf.DUMMYFUNCTION("""COMPUTED_VALUE"""),"Complete") -> Complete | F5: =IFERROR(__xludf.DUMMYFUNCTION("""COMPUTED_VALUE"""),46089.0) -> 46089
A6: =IFERROR(__xludf.DUMMYFUNCTION("""COMPUTED_VALUE"""),"Travis Stanton") -> Travis Stanton | B6: =IFERROR(__xludf.DUMMYFUNCTION("""COMPUTED_VALUE"""),"Holt") -> Holt | C6: =IFERROR(__xludf.DUMMYFUNCTION("""COMPUTED_VALUE"""),"Sustain") -> Sustain | D6: =IFERROR(__xludf.DUMMYFUNCTION("""COMPUTED_VALUE"""),"Elder") -> Elder | E6: =IFERROR(__xludf.DUMMYFUNCTION("""COMPUTED_VALUE"""),"Complete") -> Complete | F6: =IFERROR(__xludf.DUMMYFUNCTION("""COMPUTED_VALUE"""),46089.0) -> 46089
A7: =IFERROR(__xludf.DUMMYFUNCTION("""COMPUTED_VALUE"""),"Kenneth Vansconis") -> Kenneth Vansconis | B7: =IFERROR(__xludf.DUMMYFUNCTION("""COMPUTED_VALUE"""),"Portland") -> Portland | C7: =IFERROR(__xludf.DUMMYFUNCTION("""COMPUTED_VALUE"""),"Sustain") -> Sustain | D7: =IFERROR(__xludf.DUMMYFUNCTION("""COMPUTED_VALUE"""),"Elder") -> Elder | E7: =IFERROR(__xludf.DUMMYFUNCTION("""COMPUTED_VALUE"""),"Complete") -> Complete | F7: =IFERROR(__xludf.DUMMYFUNCTION("""COMPUTED_VALUE"""),46089.0) -> 46089
A8: =IFERROR(__xludf.DUMMYFUNCTION("""COMPUTED_VALUE"""),"Sue Zimmerlee") -> Sue Zimmerlee | B8: =IFERROR(__xludf.DUMMYFUNCTION("""COMPUTED_VALUE"""),"Holt") -> Holt | C8: =IFERROR(__xludf.DUMMYFUNCTION("""COMPUTED_VALUE"""),"Sustain") -> Sustain | D8: =IFERROR(__xludf.DUMMYFUNCTION("""COMPUTED_VALUE"""),"Stake Temple and Family History Consultant") -> Stake Temple and Family History Consultant | E8: =IFERROR(__xludf.DUMMYFUNCTION("""COMPUTED_VALUE"""),"Complete") -> Complete | F8: =IFERROR(__xludf.DUMMYFUNCTION("""COMPUTED_VALUE"""),45717.0) -> 45717
A9: =IFERROR(__xludf.DUMMYFUNCTION("""COMPUTED_VALUE"""),"Brit Fathi") -> Brit Fathi | B9: =IFERROR(__xludf.DUMMYFUNCTION("""COMPUTED_VALUE"""),"Holt") -> Holt | C9: =IFERROR(__xludf.DUMMYFUNCTION("""COMPUTED_VALUE"""),"Sustain") -> Sustain | D9: =IFERROR(__xludf.DUMMYFUNCTION("""COMPUTED_VALUE"""),"Stake Temple and Family History Consultant") -> Stake Temple and Family History Consultant | E9: =IFERROR(__xludf.DUMMYFUNCTION("""COMPUTED_VALUE"""),"Complete") -> Complete | F9: =IFERROR(__xludf.DUMMYFUNCTION("""COMPUTED_VALUE"""),45717.0) -> 45717
A10: =IFERROR(__xludf.DUMMYFUNCTION("""COMPUTED_VALUE"""),"Maggie Gamble") -> Maggie Gamble | B10: =IFERROR(__xludf.DUMMYFUNCTION("""COMPUTED_VALUE"""),"Williamston") -> Williamston | C10: =IFERROR(__xludf.DUMMYFUNCTION("""COMPUTED_VALUE"""),"Sustain") -> Sustain | D10: =IFERROR(__xludf.DUMMYFUNCTION("""COMPUTED_VALUE"""),"Stake JustServe Assistant Coordinator") -> Stake JustServe Assistant Coordinator | E10: =IFERROR(__xludf.DUMMYFUNCTION("""COMPUTED_VALUE"""),"Complete") -> Complete | F10: =IFERROR(__xludf.DUMMYFUNCTION("""COMPUTED_VALUE"""),45717.0) -> 45717
A11: =IFERROR(__xludf.DUMMYFUNCTION("""COMPUTED_VALUE"""),"Stephanie Prosser") -> Stephanie Prosser | B11: =IFERROR(__xludf.DUMMYFUNCTION("""COMPUTED_VALUE"""),"Holt") -> Holt | C11: =IFERROR(__xludf.DUMMYFUNCTION("""COMPUTED_VALUE"""),"Release & Thank") -> Release & Thank | D11: =IFERROR(__xludf.DUMMYFUNCTION("""COMPUTED_VALUE"""),"Stake YW Assistant Camp Director") -> Stake YW Assistant Camp Director | E11: =IFERROR(__xludf.DUMMYFUNCTION("""COMPUTED_VALUE"""),"Complete") -> Complete | F11: =IFERROR(__xludf.DUMMYFUNCTION("""COMPUTED_VALUE"""),45717.0) -> 45717
A12: =IFERROR(__xludf.DUMMYFUNCTION("""COMPUTED_VALUE"""),"Whitney Kirkham") -> Whitney Kirkham | B12: =IFERROR(__xludf.DUMMYFUNCTION("""COMPUTED_VALUE"""),"St Johns") -> St Johns | C12: =IFERROR(__xludf.DUMMYFUNCTION("""COMPUTED_VALUE"""),"Sustain") -> Sustain | D12: =IFERROR(__xludf.DUMMYFUNCTION("""COMPUTED_VALUE"""),"Stake Young Women Assistant Camp Director") -> Stake Young Women Assistant Camp Director | E12: =IFERROR(__xludf.DUMMYFUNCTION("""COMPUTED_VALUE"""),"Complete") -> Complete | F12: =IFERROR(__xludf.DUMMYFUNCTION("""COMPUTED_VALUE"""),45717.0) -> 45717
A13: =IFERROR(__xludf.DUMMYFUNCTION("""COMPUTED_VALUE"""),"David Knighton") -> David Knighton | B13: =IFERROR(__xludf.DUMMYFUNCTION("""COMPUTED_VALUE"""),"Holt") -> Holt | C13: =IFERROR(__xludf.DUMMYFUNCTION("""COMPUTED_VALUE"""),"Release & Thank") -> Release & Thank | D13: =IFERROR(__xludf.DUMMYFUNCTION("""COMPUTED_VALUE"""),"Assistant Stake Clerk") -> Assistant Stake Clerk | E13: =IFERROR(__xludf.DUMMYFUNCTION("""COMPUTED_VALUE"""),"Complete") -> Complete | F13: =IFERROR(__xludf.DUMMYFUNCTION("""COMPUTED_VALUE"""),45717.0) -> 45717
A14: =IFERROR(__xludf.DUMMYFUNCTION("""COMPUTED_VALUE"""),"Barry Godwin") -> Barry Godwin | B14: =IFERROR(__xludf.DUMMYFUNCTION("""COMPUTED_VALUE"""),"Williamston") -> Williamston | C14: =IFERROR(__xludf.DUMMYFUNCTION("""COMPUTED_VALUE"""),"Release & Thank") -> Release & Thank | D14: =IFERROR(__xludf.DUMMYFUNCTION("""COMPUTED_VALUE"""),"Stake Single Adult Representative") -> Stake Single Adult Representative | E14: =IFERROR(__xludf.DUMMYFUNCTION("""COMPUTED_VALUE"""),"Complete") -> Complete | F14: =IFERROR(__xludf.DUMMYFUNCTION("""COMPUTED_VALUE"""),45717.0) -> 45717
A15: =IFERROR(__xludf.DUMMYFUNCTION("""COMPUTED_VALUE"""),"Angie Brantley") -> Angie Brantley | B15: =IFERROR(__xludf.DUMMYFUNCTION("""COMPUTED_VALUE"""),"Jackson") -> Jackson | C15: =IFERROR(__xludf.DUMMYFUNCTION("""COMPUTED_VALUE"""),"Release & Thank") -> Release & Thank | D15: =IFERROR(__xludf.DUMMYFUNCTION("""COMPUTED_VALUE"""),"Stake Welfare and Self-Reliance Specialist") -> Stake Welfare and Self-Reliance Specialist | E15: =IFERROR(__xludf.DUMMYFUNCTION("""COMPUTED_VALUE"""),"Complete") -> Complete | F15: =IFERROR(__xludf.DUMMYFUNCTION("""COMPUTED_VALUE"""),45717.0) -> 45717
A16: =IFERROR(__xludf.DUMMYFUNCTION("""COMPUTED_VALUE"""),"Mark and Susan Joseph") -> Mark and Susan Joseph | B16: =IFERROR(__xludf.DUMMYFUNCTION("""COMPUTED_VALUE"""),"St Johns") -> St Johns | C16: =IFERROR(__xludf.DUMMYFUNCTION("""COMPUTED_VALUE"""),"Sustain") -> Sustain | D16: =IFERROR(__xludf.DUMMYFUNCTION("""COMPUTED_VALUE"""),"Stake Welfare and Self Reliance Specialists") -> Stake Welfare and Self Reliance Specialists | E16: =IFERROR(__xludf.DUMMYFUNCTION("""COMPUTED_VALUE"""),"Complete") -> Complete | F16: =IFERROR(__xludf.DUMMYFUNCTION("""COMPUTED_VALUE"""),45717.0) -> 45717
A17: =IFERROR(__xludf.DUMMYFUNCTION("""COMPUTED_VALUE"""),"Jesse Ward") -> Jesse Ward | B17: =IFERROR(__xludf.DUMMYFUNCTION("""COMPUTED_VALUE"""),"Portland") -> Portland | C17: =IFERROR(__xludf.DUMMYFUNCTION("""COMPUTED_VALUE"""),"Sustain") -> Sustain | D17: =IFERROR(__xludf.DUMMYFUNCTION("""COMPUTED_VALUE"""),"Elder") -> Elder | E17: =IFERROR(__xludf.DUMMYFUNCTION("""COMPUTED_VALUE"""),"Complete") -> Complete | F17: =IFERROR(__xludf.DUMMYFUNCTION("""COMPUTED_VALUE"""),45717.0) -> 45717
A18: =IFERROR(__xludf.DUMMYFUNCTION("""COMPUTED_VALUE"""),"Rusty Joseph King") -> Rusty Joseph King | B18: =IFERROR(__xludf.DUMMYFUNCTION("""COMPUTED_VALUE"""),"Jackson") -> Jackson | C18: =IFERROR(__xludf.DUMMYFUNCTION("""COMPUTED_VALUE"""),"Sustain") -> Sustain | D18: =IFERROR(__xludf.DUMMYFUNCTION("""COMPUTED_VALUE"""),"Elder") -> Elder | E18: =IFERROR(__xludf.DUMMYFUNCTION("""COMPUTED_VALUE"""),"Complete") -> Complete | F18: =IFERROR(__xludf.DUMMYFUNCTION("""COMPUTED_VALUE"""),45717.0) -> 45717
A19: =IFERROR(__xludf.DUMMYFUNCTION("""COMPUTED_VALUE"""),"Allen Scheck") -> Allen Scheck | B19: =IFERROR(__xludf.DUMMYFUNCTION("""COMPUTED_VALUE"""),"Williamston") -> Williamston | C19: =IFERROR(__xludf.DUMMYFUNCTION("""COMPUTED_VALUE"""),"Release & Thank") -> Release & Thank | D19: =IFERROR(__xludf.DUMMYFUNCTION("""COMPUTED_VALUE"""),"Stake Executive Secretary ") -> Stake Executive Secretary | E19: =IFERROR(__xludf.DUMMYFUNCTION("""COMPUTED_VALUE"""),"Complete") -> Complete | F19: =IFERROR(__xludf.DUMMYFUNCTION("""COMPUTED_VALUE"""),45536.0) -> 45536
A20: =IFERROR(__xludf.DUMMYFUNCTION("""COMPUTED_VALUE"""),"Chris Hilgendorf") -> Chris Hilgendorf | B20: =IFERROR(__xludf.DUMMYFUNCTION("""COMPUTED_VALUE"""),"Williamston") -> Williamston | C20: =IFERROR(__xludf.DUMMYFUNCTION("""COMPUTED_VALUE"""),"Sustain") -> Sustain | D20: =IFERROR(__xludf.DUMMYFUNCTION("""COMPUTED_VALUE"""),"Stake Executive Secretary") -> Stake Executive Secretary | E20: =IFERROR(__xludf.DUMMYFUNCTION("""COMPUTED_VALUE"""),"Complete") -> Complete | F20: =IFERROR(__xludf.DUMMYFUNCTION("""COMPUTED_VALUE"""),45536.0) -> 45536
A21: =IFERROR(__xludf.DUMMYFUNCTION("""COMPUTED_VALUE"""),"Elliott Renin Earl") -> Elliott Renin Earl | B21: =IFERROR(__xludf.DUMMYFUNCTION("""COMPUTED_VALUE"""),"St Johns") -> St Johns | C21: =IFERROR(__xludf.DUMMYFUNCTION("""COMPUTED_VALUE"""),"Sustain") -> Sustain | D21: =IFERROR(__xludf.DUMMYFUNCTION("""COMPUTED_VALUE"""),"Elder") -> Elder | E21: =IFERROR(__xludf.DUMMYFUNCTION("""COMPUTED_VALUE"""),"Complete") -> Complete | F21: =IFERROR(__xludf.DUMMYFUNCTION("""COMPUTED_VALUE"""),45536.0) -> 45536
A22: =IFERROR(__xludf.DUMMYFUNCTION("""COMPUTED_VALUE"""),"Mark Bell") -> Mark Bell | B22: =IFERROR(__xludf.DUMMYFUNCTION("""COMPUTED_VALUE"""),"Holt") -> Holt | C22: =IFERROR(__xludf.DUMMYFUNCTION("""COMPUTED_VALUE"""),"Sustain") -> Sustain | D22: =IFERROR(__xludf.DUMMYFUNCTION("""COMPUTED_VALUE"""),"High Priest") -> High Priest | E22: =IFERROR(__xludf.DUMMYFUNCTION("""COMPUTED_VALUE"""),"Complete") -> Complete | F22: =IFERROR(__xludf.DUMMYFUNCTION("""COMPUTED_VALUE"""),45536.0) -> 45536
A23: =IFERROR(__xludf.DUMMYFUNCTION("""COMPUTED_VALUE"""),"Nick Warren") -> Nick Warren | B23: =IFERROR(__xludf.DUMMYFUNCTION("""COMPUTED_VALUE"""),"Lansing") -> Lansing | C23: =IFERROR(__xludf.DUMMYFUNCTION("""COMPUTED_VALUE"""),"Release & Thank") -> Release & Thank | D23: =IFERROR(__xludf.DUMMYFUNCTION("""COMPUTED_VALUE"""),"Stake High Councilor") -> Stake High Councilor | E23: =IFERROR(__xludf.DUMMYFUNCTION("""COMPUTED_VALUE"""),"Complete") -> Complete | F23: =IFERROR(__xludf.DUMMYFUNCTION("""COMPUTED_VALUE"""),45536.0) -> 45536
A24: =IFERROR(__xludf.DUMMYFUNCTION("""COMPUTED_VALUE"""),"Ken Bills") -> Ken Bills | B24: =IFERROR(__xludf.DUMMYFUNCTION("""COMPUTED_VALUE"""),"Williamston") -> Williamston | C24: =IFERROR(__xludf.DUMMYFUNCTION("""COMPUTED_VALUE"""),"Sustain") -> Sustain | D24: =IFERROR(__xludf.DUMMYFUNCTION("""COMPUTED_VALUE"""),"Stake High Councilor") -> Stake High Councilor | E24: =IFERROR(__xludf.DUMMYFUNCTION("""COMPUTED_VALUE"""),"Complete") -> Complete | F24: =IFERROR(__xludf.DUMMYFUNCTION("""COMPUTED_VALUE"""),45536.0) -> 45536
A25: =IFERROR(__xludf.DUMMYFUNCTION("""COMPUTED_VALUE"""),"Ian McCrary") -> Ian McCrary | B25: =IFERROR(__xludf.DUMMYFUNCTION("""COMPUTED_VALUE"""),"Lansing") -> Lansing | C25: =IFERROR(__xludf.DUMMYFUNCTION("""COMPUTED_VALUE"""),"Sustain") -> Sustain | D25: =IFERROR(__xludf.DUMMYFUNCTION("""COMPUTED_VALUE"""),"Stake High Councilor") -> Stake High Councilor | E25: =IFERROR(__xludf.DUMMYFUNCTION("""COMPUTED_VALUE"""),"Complete") -> Complete | F25: =IFERROR(__xludf.DUMMYFUNCTION("""COMPUTED_VALUE"""),45536.0) -> 45536
A26: =IFERROR(__xludf.DUMMYFUNCTION("""COMPUTED_VALUE"""),"Doug Neil") -> Doug Neil | B26: =IFERROR(__xludf.DUMMYFUNCTION("""COMPUTED_VALUE"""),"Williamston") -> Williamston | C26: =IFERROR(__xludf.DUMMYFUNCTION("""COMPUTED_VALUE"""),"Release & Thank") -> Release & Thank | D26: =IFERROR(__xludf.DUMMYFUNCTION("""COMPUTED_VALUE"""),"Asst. Stake Clerk - Finance") -> Asst. Stake Clerk - Finance | E26: =IFERROR(__xludf.DUMMYFUNCTION("""COMPUTED_VALUE"""),"Complete") -> Complete | F26: =IFERROR(__xludf.DUMMYFUNCTION("""COMPUTED_VALUE"""),45536.0) -> 45536
A27: =IFERROR(__xludf.DUMMYFUNCTION("""COMPUTED_VALUE"""),"Don Ward") -> Don Ward | B27: =IFERROR(__xludf.DUMMYFUNCTION("""COMPUTED_VALUE"""),"Williamston") -> Williamston | C27: =IFERROR(__xludf.DUMMYFUNCTION("""COMPUTED_VALUE"""),"Sustain") -> Sustain | D27: =IFERROR(__xludf.DUMMYFUNCTION("""COMPUTED_VALUE"""),"Asst. Stake Clerk - Finance") -> Asst. Stake Clerk - Finance | E27: =IFERROR(__xludf.DUMMYFUNCTION("""COMPUTED_VALUE"""),"Complete") -> Complete | F27: =IFERROR(__xludf.DUMMYFUNCTION("""COMPUTED_VALUE"""),45536.0) -> 45536
A28: =IFERROR(__xludf.DUMMYFUNCTION("""COMPUTED_VALUE"""),"Landon Bartlett") -> Landon Bartlett | B28: =IFERROR(__xludf.DUMMYFUNCTION("""COMPUTED_VALUE"""),"Williamston") -> Williamston | C28: =IFERROR(__xludf.DUMMYFUNCTION("""COMPUTED_VALUE"""),"Release & Thank") -> Release & Thank | D28: =IFERROR(__xludf.DUMMYFUNCTION("""COMPUTED_VALUE"""),"Stake High Councilor - YM 2nd Counselor") -> Stake High Councilor - YM 2nd Counselor | E28: =IFERROR(__xludf.DUMMYFUNCTION("""COMPUTED_VALUE"""),"Complete") -> Complete | F28: =IFERROR(__xludf.DUMMYFUNCTION("""COMPUTED_VALUE"""),45536.0) -> 45536
A29: =IFERROR(__xludf.DUMMYFUNCTION("""COMPUTED_VALUE"""),"Mark Bell") -> Mark Bell | B29: =IFERROR(__xludf.DUMMYFUNCTION("""COMPUTED_VALUE"""),"Holt") -> Holt | C29: =IFERROR(__xludf.DUMMYFUNCTION("""COMPUTED_VALUE"""),"Sustain") -> Sustain | D29: =IFERROR(__xludf.DUMMYFUNCTION("""COMPUTED_VALUE"""),"Stake High Councilor - YM 2nd Counselor") -> Stake High Councilor - YM 2nd Counselor | E29: =IFERROR(__xludf.DUMMYFUNCTION("""COMPUTED_VALUE"""),"Complete") -> Complete | F29: =IFERROR(__xludf.DUMMYFUNCTION("""COMPUTED_VALUE"""),45536.0) -> 45536
A30: =IFERROR(__xludf.DUMMYFUNCTION("""COMPUTED_VALUE"""),"Calvin Vos") -> Calvin Vos | B30: =IFERROR(__xludf.DUMMYFUNCTION("""COMPUTED_VALUE"""),"YSA") -> YSA | C30: =IFERROR(__xludf.DUMMYFUNCTION("""COMPUTED_VALUE"""),"Release & Thank") -> Release & Thank | D30: =IFERROR(__xludf.DUMMYFUNCTION("""COMPUTED_VALUE"""),"Stake Assistant executive security") -> Stake Assistant executive security | E30: =IFERROR(__xludf.DUMMYFUNCTION("""COMPUTED_VALUE"""),"Complete") -> Complete | F30: =IFERROR(__xludf.DUMMYFUNCTION("""COMPUTED_VALUE"""),45536.0) -> 45536
A31: =IFERROR(__xludf.DUMMYFUNCTION("""COMPUTED_VALUE"""),"David Hall") -> David Hall | B31: =IFERROR(__xludf.DUMMYFUNCTION("""COMPUTED_VALUE"""),"Williamston") -> Williamston | C31: =IFERROR(__xludf.DUMMYFUNCTION("""COMPUTED_VALUE"""),"Release & Thank") -> Release & Thank | D31: =IFERROR(__xludf.DUMMYFUNCTION("""COMPUTED_VALUE"""),"Stake High Council") -> Stake High Council | E31: =IFERROR(__xludf.DUMMYFUNCTION("""COMPUTED_VALUE"""),"Complete") -> Complete | F31: =IFERROR(__xludf.DUMMYFUNCTION("""COMPUTED_VALUE"""),45536.0) -> 45536
A32: =IFERROR(__xludf.DUMMYFUNCTION("""COMPUTED_VALUE"""),"Tom and Stephanie Smith") -> Tom and Stephanie Smith | B32: =IFERROR(__xludf.DUMMYFUNCTION("""COMPUTED_VALUE"""),"St Johns") -> St Johns | C32: =IFERROR(__xludf.DUMMYFUNCTION("""COMPUTED_VALUE"""),"Release & Thank") -> Release & Thank | D32: =IFERROR(__xludf.DUMMYFUNCTION("""COMPUTED_VALUE"""),"Stake Single Adult Advisers") -> Stake Single Adult Advisers | E32: =IFERROR(__xludf.DUMMYFUNCTION("""COMPUTED_VALUE"""),"Complete") -> Complete | F32: =IFERROR(__xludf.DUMMYFUNCTION("""COMPUTED_VALUE"""),45536.0) -> 45536
A33: =IFERROR(__xludf.DUMMYFUNCTION("""COMPUTED_VALUE"""),"David Hall") -> David Hall | B33: =IFERROR(__xludf.DUMMYFUNCTION("""COMPUTED_VALUE"""),"Williamston") -> Williamston | C33: =IFERROR(__xludf.DUMMYFUNCTION("""COMPUTED_VALUE"""),"Sustain") -> Sustain | D33: =IFERROR(__xludf.DUMMYFUNCTION("""COMPUTED_VALUE"""),"Stake YM Specialist") -> Stake YM Specialist | E33: =IFERROR(__xludf.DUMMYFUNCTION("""COMPUTED_VALUE"""),"Complete") -> Complete | F33: =IFERROR(__xludf.DUMMYFUNCTION("""COMPUTED_VALUE"""),45536.0) -> 45536
A34: =IFERROR(__xludf.DUMMYFUNCTION("""COMPUTED_VALUE"""),"Barry Godwin") -> Barry Godwin | B34: =IFERROR(__xludf.DUMMYFUNCTION("""COMPUTED_VALUE"""),"Williamston") -> Williamston | C34: =IFERROR(__xludf.DUMMYFUNCTION("""COMPUTED_VALUE"""),"Sustain") -> Sustain | D34: =IFERROR(__xludf.DUMMYFUNCTION("""COMPUTED_VALUE"""),"Stake Single Adult Representative") -> Stake Single Adult Representative | E34: =IFERROR(__xludf.DUMMYFUNCTION("""COMPUTED_VALUE"""),"Complete") -> Complete | F34: =IFERROR(__xludf.DUMMYFUNCTION("""COMPUTED_VALUE"""),45536.0) -> 45536
A35: =IFERROR(__xludf.DUMMYFUNCTION("""COMPUTED_VALUE"""),"Conan Heiselt") -> Conan Heiselt | B35: =IFERROR(__xludf.DUMMYFUNCTION("""COMPUTED_VALUE"""),"Holt") -> Holt | C35: =IFERROR(__xludf.DUMMYFUNCTION("""COMPUTED_VALUE"""),"Sustain") -> Sustain | D35: =IFERROR(__xludf.DUMMYFUNCTION("""COMPUTED_VALUE"""),"Stake Technology Specialist") -> Stake Technology Specialist | E35: =IFERROR(__xludf.DUMMYFUNCTION("""COMPUTED_VALUE"""),"Complete") -> Complete | F35: =IFERROR(__xludf.DUMMYFUNCTION("""COMPUTED_VALUE"""),45536.0) -> 45536
A36: =IFERROR(__xludf.DUMMYFUNCTION("""COMPUTED_VALUE"""),"Noah Wood") -> Noah Wood | B36: =IFERROR(__xludf.DUMMYFUNCTION("""COMPUTED_VALUE"""),"Jackson") -> Jackson | C36: =IFERROR(__xludf.DUMMYFUNCTION("""COMPUTED_VALUE"""),"Sustain") -> Sustain | D36: =IFERROR(__xludf.DUMMYFUNCTION("""COMPUTED_VALUE"""),"Elder") -> Elder | E36: =IFERROR(__xludf.DUMMYFUNCTION("""COMPUTED_VALUE"""),"Complete") -> Complete | F36: =IFERROR(__xludf.DUMMYFUNCTION("""COMPUTED_VALUE"""),45536.0) -> 45536
A37: =IFERROR(__xludf.DUMMYFUNCTION("""COMPUTED_VALUE"""),"Travis Sybrowsky") -> Travis Sybrowsky | B37: =IFERROR(__xludf.DUMMYFUNCTION("""COMPUTED_VALUE"""),"Portland") -> Portland | C37: =IFERROR(__xludf.DUMMYFUNCTION("""COMPUTED_VALUE"""),"Sustain") -> Sustain | D37: =IFERROR(__xludf.DUMMYFUNCTION("""COMPUTED_VALUE"""),"Stake Seminary Teacher") -> Stake Seminary Teacher | E37: =IFERROR(__xludf.DUMMYFUNCTION("""COMPUTED_VALUE"""),"Complete") -> Complete | F37: =IFERROR(__xludf.DUMMYFUNCTION("""COMPUTED_VALUE"""),45536.0) -> 45536
A38: =IFERROR(__xludf.DUMMYFUNCTION("""COMPUTED_VALUE"""),"Sister Michael (Mickey) Jeanne Tuelle") -> Sister Michael (Mickey) Jeanne Tuelle | B38: =IFERROR(__xludf.DUMMYFUNCTION("""COMPUTED_VALUE"""),"Charlotte") -> Charlotte | C38: =IFERROR(__xludf.DUMMYFUNCTION("""COMPUTED_VALUE"""),"Sustain") -> Sustain | D38: =IFERROR(__xludf.DUMMYFUNCTION("""COMPUTED_VALUE"""),"Stake Single Adult Representative") -> Stake Single Adult Representative | E38: =IFERROR(__xludf.DUMMYFUNCTION("""COMPUTED_VALUE"""),"Complete") -> Complete | F38: =IFERROR(__xludf.DUMMYFUNCTION("""COMPUTED_VALUE"""),45352.0) -> 45352
